<!--
  Copyright 2016 The Cartographer Authors

  Licensed under the Apache License, Version 2.0 (the "License");
  you may not use this file except in compliance with the License.
  You may obtain a copy of the License at

       http://www.apache.org/licenses/LICENSE-2.0

  Unless required by applicable law or agreed to in writing, software
  distributed under the License is distributed on an "AS IS" BASIS,
  WITHOUT WARRANTIES OR CONDITIONS OF ANY KIND, either express or implied.
  See the License for the specific language governing permissions and
  limitations under the License.
-->

<robot name="amigo_bot">
  <!-- Defino algunos colores que se repiten -->
  <material name="orange">
    <color rgba="1.0 0.5 0.2 1" />
  </material>
  <material name="gray">
    <color rgba="0.2 0.2 0.2 1" />
  </material>

  <!-- VINCULOS -->

  <!-- Cuerpo del AmigoBot -->
  <link name="base_link">
    <inertial>
      <mass value="3.6"/>
      <origin xyz="0 0 0"/>
      <inertia ixx="1" ixy="0" ixz="0" iyy="1" iyz="0" izz="1"/>
    </inertial>
    <visual>
      <origin rpy="0 0 0" xyz="0 0 0.075"/>
      <geometry>
        <box size="0.36 0.28 0.15" />
      </geometry>
      <material name="ChassisRed">
        <color rgba="0.851 0.0 0.0 1.0"/>
      </material>
    </visual>
    <collision>
      <origin rpy="0 0 0" xyz="0 0 0"/>
      <geometry>
        <box size="0.01 0.01 0.01"/>
      </geometry>
    </collision>
  </link>

  <!-- Plataforma que sostiene al pan/tilt -->
  <link name="plataforma_link">
    <visual>
      <origin xyz="0 0 0" rpy="0 0 1.5708"/>
      <geometry>
        <box size="0.12 0.08 0.002" />
      </geometry>
      <material name="orange" />
    </visual>
  </link>

  <!-- Cuerpo del servo y brazo del pan -->
	<link name="brazo_pan_link">
		<visual>
		  <origin xyz="0 0 0" rpy="0 0 0" />
		  <geometry>
		    <cylinder radius="0.01" length=".06" />
		  </geometry>
		  <material name="gray">
		    <color rgba=".2 .2 .2 1" />
		  </material>
		</visual>
	</link>

  <!-- Cuerpo del servo y brazo del tilt -->
	<link name="brazo_tilt_link">
		<visual>
		  <origin xyz="0 0 0.0425" rpy="0 0 0" />
		  <geometry>
		    <cylinder radius="0.01" length=".085" />
		  </geometry>
		  <material name="gray">
		    <color rgba=".2 .2 .2 1" />
		  </material>
		</visual>
	</link>

  <!-- Posicion de una posible IMU -->
  <link name="imu_link">
    <visual>
      <origin xyz="0 0 0" />
      <geometry>
        <box size="0.01 0.01 0.01" />
      </geometry>
      <material name="gray" />
    </visual>
  </link>

  <!-- Cuerpo del Hokuyo -->
  <link name="laser">
    <visual>
      <origin xyz="0 0 0" />
      <geometry>
        <box size="0.03 0.02 0.02" />
      </geometry>
      <material name="orange" />
    </visual>
  </link>

  <!-- ARTICULACIONES -->

  <!-- Union Fija del AmigoBot con la plataforma -->
  <joint name="plataforma_joint" type="fixed">
    <parent link="base_link" />
    <child link="plataforma_link" />
    <origin xyz="0.1 0 0.15" />
  </joint>

  <!-- Union Revolute de la plataforma con la parte fija del pan -->
	<joint name="pan_joint" type="revolute">
		<parent link="plataforma_link"/>
		<child link="brazo_pan_link"/>
		<origin xyz="0 0 0.03" rpy="0 3.1416 -1.5708" />
		<axis xyz="0 0 1" />
		<limit upper="1.5708" lower="-1.5708" effort="10" velocity="10" />
	</joint>

  <!-- Union Revolute de la parte fija del pan con la parte fija del tilt -->
	<joint name="tilt_joint" type="revolute">
		<parent link="brazo_pan_link"/>
		<child link="brazo_tilt_link"/>
		<origin xyz="0 0 -0.03" rpy="0 1.5708 0" />
		<axis xyz="0 1 0" />
		<limit upper="1.5708" lower="-1.5708" effort="10" velocity="10" />
	</joint>

  <!-- Union Fija de la parte fija del Tilt con el Hokuyo -->
  <joint name="laser_joint" type="fixed">
    <parent link="brazo_tilt_link" />
    <child link="laser" />
    <origin xyz="0.005 0 0.085" rpy="3.1416 -1.5708 0" />
  </joint>

  <!-- Union Fija de la posible imu con brazo tilt -->
  <joint name="imu_joint" type="fixed">
    <parent link="brazo_tilt_link" />
    <child link="imu_link" />
    <origin xyz="-0.01 0 0.085" rpy="3.1416 -1.5708 0" />
  </joint>







<!-- LASER SLAM -->

<!-- Cuerpo del servo y brazo del pan -->
  <link name="brazo_pan_link_fijo">
    <visual>
      <origin xyz="0 0 0" rpy="0 0 0" />
      <geometry>
        <cylinder radius="0.01" length=".06" />
      </geometry>
      <material name="gray">
        <color rgba=".2 .2 .2 1" />
      </material>
    </visual>
  </link>

  <!-- Cuerpo del servo y brazo del tilt -->
  <link name="brazo_tilt_link_fijo">
    <visual>
      <origin xyz="0 0 0.0425" rpy="0 0 0" />
      <geometry>
        <cylinder radius="0.01" length=".085" />
      </geometry>
      <material name="gray">
        <color rgba=".2 .2 .2 1" />
      </material>
    </visual>
  </link>

  <!-- Cuerpo del Hokuyo -->
  <link name="laser_slam">
    <visual>
      <origin xyz="0 0 0" />
      <geometry>
        <box size="0.03 0.02 0.02" />
      </geometry>
      <material name="orange" />
    </visual>
  </link>

<!-- Union Revolute de la plataforma con la parte fija del pan -->
  <joint name="pan_joint_fijo" type="fixed">
    <parent link="plataforma_link"/>
    <child link="brazo_pan_link_fijo"/>
    <!--origin xyz="0 0 0.03" rpy="0 3.1416 -1.5708" /-->
    <origin xyz="0 0 0.03" rpy="0 3.1416 -3.124146667" />
  </joint>

  <!-- Union Revolute de la parte fija del pan con la parte fija del tilt -->
  <joint name="tilt_joint_fijo" type="fixed">
    <parent link="brazo_pan_link_fijo"/>
    <child link="brazo_tilt_link_fijo"/>
    <!--origin xyz="0 0 -0.03" rpy="0 1.5708 0" /-->
    <origin xyz="0 0 -0.03" rpy="0 1.588253333 0" />
  </joint>

  <!-- Union Fija de la parte fija del Tilt con el Hokuyo -->
  <joint name="laser_joint_fijo" type="fixed">
    <parent link="brazo_tilt_link_fijo" />
    <child link="laser_slam" />
    <origin xyz="0.005 0 0.085" rpy="3.1416 -1.5708 0" />
  </joint>

</robot>
